[36m[2025-04-26 22:24:55 DEBUG] [__init__:101][39m ###############################################################################
[36m[2025-04-26 22:24:55 DEBUG] [__init__:102][39m Running command 'run'
[36m[2025-04-26 22:24:55 DEBUG] [__init__:106][39m Using settings file 'C:\Users\Eduar\.chaostoolkit\settings.yaml'
[36m[2025-04-26 22:24:55 DEBUG] [settings:31][39m The Chaos Toolkit settings file could not be found at 'C:\Users\Eduar\.chaostoolkit\settings.yaml'.
[36m[2025-04-26 22:24:55 DEBUG] [__init__:472][39m No controls to apply on 'loader'
[36m[2025-04-26 22:24:55 DEBUG] [__init__:472][39m No controls to apply on 'loader'
[36m[2025-04-26 22:24:55 DEBUG] [caching:24][39m Building activity cache...
[36m[2025-04-26 22:24:55 DEBUG] [caching:35][39m Cached 4 activities
[32m[2025-04-26 22:24:55 INFO] [experiment:59][39m Validating the experiment's syntax
[36m[2025-04-26 22:24:55 DEBUG] [configuration:64][39m Loading configuration...
[36m[2025-04-26 22:24:55 DEBUG] [secret:79][39m Loading secrets...
[36m[2025-04-26 22:24:55 DEBUG] [secret:104][39m Done loading secrets
[32m[2025-04-26 22:24:55 INFO] [experiment:112][39m Experiment looks valid
[36m[2025-04-26 22:24:55 DEBUG] [caching:42][39m Clearing activities cache
[36m[2025-04-26 22:24:55 DEBUG] [run:224][39m Runtime strategies: hypothesis - default / rollbacks - default
[36m[2025-04-26 22:24:55 DEBUG] [caching:24][39m Building activity cache...
[36m[2025-04-26 22:24:55 DEBUG] [caching:35][39m Cached 4 activities
[36m[2025-04-26 22:24:55 DEBUG] [configuration:64][39m Loading configuration...
[36m[2025-04-26 22:24:55 DEBUG] [secret:79][39m Loading secrets...
[36m[2025-04-26 22:24:55 DEBUG] [secret:104][39m Done loading secrets
[36m[2025-04-26 22:24:55 DEBUG] [configuration:161][39m Loading dynamic configuration...
[36m[2025-04-26 22:24:55 DEBUG] [exit:91][39m System 'Windows-11-10.0.26100-SP0' does not expose SIGUSR signals
[32m[2025-04-26 22:24:55 INFO] [run:440][39m Running experiment: Teste simples de falha no Redis
[36m[2025-04-26 22:24:55 DEBUG] [__init__:67][39m Initializing controls
[32m[2025-04-26 22:24:55 INFO] [run:471][39m Steady-state strategy: default
[32m[2025-04-26 22:24:55 INFO] [run:477][39m Rollbacks strategy: default
[36m[2025-04-26 22:24:55 DEBUG] [__init__:472][39m No controls to apply on 'experiment'
[36m[2025-04-26 22:24:55 DEBUG] [run:654][39m Running steady-state hypothesis before the method
[32m[2025-04-26 22:24:55 INFO] [hypothesis:205][39m Steady state hypothesis: Aplica√ß√£o est√° saud√°vel
[36m[2025-04-26 22:24:55 DEBUG] [__init__:472][39m No controls to apply on 'hypothesis'
[36m[2025-04-26 22:24:55 DEBUG] [__init__:472][39m No controls to apply on 'activity'
[32m[2025-04-26 22:24:55 INFO] [activity:232][39m Probe: verifica_servico_aplicacao
[36m[2025-04-26 22:24:58 DEBUG] [activity:317][39m Activity failed
    Traceback (most recent call last):
      File "C:\Users\Eduar\AppData\Roaming\Python\Python313\site-packages\urllib3\connectionpool.py", line 534, in _make_request
        response = conn.getresponse()
      File "C:\Users\Eduar\AppData\Roaming\Python\Python313\site-packages\urllib3\connection.py", line 516, in getresponse
        httplib_response = super().getresponse()
      File "C:\Python313\Lib\http\client.py", line 1430, in getresponse
        response.begin()
        ~~~~~~~~~~~~~~^^
      File "C:\Python313\Lib\http\client.py", line 331, in begin
        version, status, reason = self._read_status()
                                  ~~~~~~~~~~~~~~~~~^^
      File "C:\Python313\Lib\http\client.py", line 292, in _read_status
        line = str(self.fp.readline(_MAXLINE + 1), "iso-8859-1")
                   ~~~~~~~~~~~~~~~~^^^^^^^^^^^^^^
      File "C:\Python313\Lib\socket.py", line 719, in readinto
        return self._sock.recv_into(b)
               ~~~~~~~~~~~~~~~~~~~~^^^
    TimeoutError: timed out
    
    The above exception was the direct cause of the following exception:
    
    Traceback (most recent call last):
      File "C:\Users\Eduar\AppData\Roaming\Python\Python313\site-packages\requests\adapters.py", line 667, in send
        resp = conn.urlopen(
            method=request.method,
        ...<9 lines>...
            chunked=chunked,
        )
      File "C:\Users\Eduar\AppData\Roaming\Python\Python313\site-packages\urllib3\connectionpool.py", line 841, in urlopen
        retries = retries.increment(
            method, url, error=new_e, _pool=self, _stacktrace=sys.exc_info()[2]
        )
      File "C:\Users\Eduar\AppData\Roaming\Python\Python313\site-packages\urllib3\util\retry.py", line 474, in increment
        raise reraise(type(error), error, _stacktrace)
              ~~~~~~~^^^^^^^^^^^^^^^^^^^^^^^^^^^^^^^^^
      File "C:\Users\Eduar\AppData\Roaming\Python\Python313\site-packages\urllib3\util\util.py", line 39, in reraise
        raise value
      File "C:\Users\Eduar\AppData\Roaming\Python\Python313\site-packages\urllib3\connectionpool.py", line 787, in urlopen
        response = self._make_request(
            conn,
        ...<10 lines>...
            **response_kw,
        )
      File "C:\Users\Eduar\AppData\Roaming\Python\Python313\site-packages\urllib3\connectionpool.py", line 536, in _make_request
        self._raise_timeout(err=e, url=url, timeout_value=read_timeout)
        ~~~~~~~~~~~~~~~~~~~^^^^^^^^^^^^^^^^^^^^^^^^^^^^^^^^^^^^^^^^^^^^
      File "C:\Users\Eduar\AppData\Roaming\Python\Python313\site-packages\urllib3\connectionpool.py", line 367, in _raise_timeout
        raise ReadTimeoutError(
            self, url, f"Read timed out. (read timeout={timeout_value})"
        ) from err
    urllib3.exceptions.ReadTimeoutError: HTTPConnectionPool(host='localhost', port=3000): Read timed out. (read timeout=3)
    
    During handling of the above exception, another exception occurred:
    
    Traceback (most recent call last):
      File "C:\Users\Eduar\AppData\Roaming\Python\Python313\site-packages\chaoslib\provider\http.py", line 51, in run_http_activity
        r = s.get(
            url,
        ...<3 lines>...
            verify=verify_tls,
        )
      File "C:\Users\Eduar\AppData\Roaming\Python\Python313\site-packages\requests\sessions.py", line 602, in get
        return self.request("GET", url, **kwargs)
               ~~~~~~~~~~~~^^^^^^^^^^^^^^^^^^^^^^
      File "C:\Users\Eduar\AppData\Roaming\Python\Python313\site-packages\requests\sessions.py", line 589, in request
        resp = self.send(prep, **send_kwargs)
      File "C:\Users\Eduar\AppData\Roaming\Python\Python313\site-packages\requests\sessions.py", line 703, in send
        r = adapter.send(request, **kwargs)
      File "C:\Users\Eduar\AppData\Roaming\Python\Python313\site-packages\requests\adapters.py", line 713, in send
        raise ReadTimeout(e, request=request)
    requests.exceptions.ReadTimeout: HTTPConnectionPool(host='localhost', port=3000): Read timed out. (read timeout=3)
    
    During handling of the above exception, another exception occurred:
    
    Traceback (most recent call last):
      File "C:\Users\Eduar\AppData\Roaming\Python\Python313\site-packages\chaoslib\activity.py", line 314, in run_activity
        result = run_http_activity(activity, configuration, secrets)
      File "C:\Users\Eduar\AppData\Roaming\Python\Python313\site-packages\chaoslib\provider\http.py", line 103, in run_http_activity
        raise ActivityFailed("activity took too long to complete")
    chaoslib.exceptions.ActivityFailed: activity took too long to complete
[31m[2025-04-26 22:24:58 ERROR] [activity:268][39m   => failed: activity took too long to complete
[36m[2025-04-26 22:24:58 DEBUG] [__init__:472][39m No controls to apply on 'activity'
[33m[2025-04-26 22:24:58 WARNING] [hypothesis:232][39m Probe terminated unexpectedly, so its tolerance could not be validated
[36m[2025-04-26 22:24:58 DEBUG] [__init__:472][39m No controls to apply on 'hypothesis'
[31m[2025-04-26 22:24:58 CRITICAL] [run:674][39m Steady state probe 'verifica_servico_aplicacao' is not in the given tolerance so failing this experiment
[32m[2025-04-26 22:24:58 INFO] [run:598][39m Experiment ended with status: failed
[36m[2025-04-26 22:24:58 DEBUG] [__init__:472][39m No controls to apply on 'experiment'
[36m[2025-04-26 22:24:58 DEBUG] [__init__:106][39m Cleaning up controls
[36m[2025-04-26 22:24:58 DEBUG] [caching:42][39m Clearing activities cache
